[2023-09-01 11:31:36 +0800] [4220] [INFO] Sanic v23.6.0
2023-09-01 11:31:36,419 [INFO] - Sanic v23.6.0
[2023-09-01 11:31:36 +0800] [4220] [INFO] Goin' Fast @ http://localhost:9999
2023-09-01 11:31:36,419 [INFO] - Goin' Fast @ http://localhost:9999
[2023-09-01 11:31:36 +0800] [4220] [INFO] mode: production, single worker
2023-09-01 11:31:36,419 [INFO] - mode: production, single worker
[2023-09-01 11:31:36 +0800] [4220] [INFO] server: sanic, HTTP/1.1
2023-09-01 11:31:36,420 [INFO] - server: sanic, HTTP/1.1
[2023-09-01 11:31:36 +0800] [4220] [INFO] python: 3.8.17
2023-09-01 11:31:36,420 [INFO] - python: 3.8.17
[2023-09-01 11:31:36 +0800] [4220] [INFO] platform: macOS-10.16-x86_64-i386-64bit
2023-09-01 11:31:36,420 [INFO] - platform: macOS-10.16-x86_64-i386-64bit
[2023-09-01 11:31:36 +0800] [4220] [INFO] packages: sanic-routing==23.6.0
2023-09-01 11:31:36,420 [INFO] - packages: sanic-routing==23.6.0
[2023-09-01 11:31:36 +0800] [4230] [INFO] Starting worker [4230]
2023-09-01 11:31:36,793 [INFO] - Starting worker [4230]
[2023-09-01 11:42:34 +0800] [17559] [INFO] Sanic v23.6.0
2023-09-01 11:42:34,784 [INFO] - Sanic v23.6.0
[2023-09-01 11:42:34 +0800] [17559] [INFO] Goin' Fast @ http://localhost:9999
2023-09-01 11:42:34,784 [INFO] - Goin' Fast @ http://localhost:9999
[2023-09-01 11:42:34 +0800] [17559] [INFO] mode: production, single worker
2023-09-01 11:42:34,784 [INFO] - mode: production, single worker
[2023-09-01 11:42:34 +0800] [17559] [INFO] server: sanic, HTTP/1.1
2023-09-01 11:42:34,784 [INFO] - server: sanic, HTTP/1.1
[2023-09-01 11:42:34 +0800] [17559] [INFO] python: 3.8.17
2023-09-01 11:42:34,784 [INFO] - python: 3.8.17
[2023-09-01 11:42:34 +0800] [17559] [INFO] platform: macOS-10.16-x86_64-i386-64bit
2023-09-01 11:42:34,784 [INFO] - platform: macOS-10.16-x86_64-i386-64bit
[2023-09-01 11:42:34 +0800] [17559] [INFO] packages: sanic-routing==23.6.0
2023-09-01 11:42:34,784 [INFO] - packages: sanic-routing==23.6.0
[2023-09-01 11:42:35 +0800] [17567] [INFO] Starting worker [17567]
2023-09-01 11:42:35,158 [INFO] - Starting worker [17567]
2023-09-01 11:42:41,929 [INFO] - 我在尝试写shell脚本
[2023-09-01 13:51:43 +0800] [68137] [INFO] Sanic v23.6.0
2023-09-01 13:51:43,850 [INFO] - Sanic v23.6.0
[2023-09-01 13:51:43 +0800] [68137] [INFO] Goin' Fast @ http://localhost:9999
2023-09-01 13:51:43,851 [INFO] - Goin' Fast @ http://localhost:9999
[2023-09-01 13:51:43 +0800] [68137] [INFO] mode: production, single worker
2023-09-01 13:51:43,851 [INFO] - mode: production, single worker
[2023-09-01 13:51:43 +0800] [68137] [INFO] server: sanic, HTTP/1.1
2023-09-01 13:51:43,851 [INFO] - server: sanic, HTTP/1.1
[2023-09-01 13:51:43 +0800] [68137] [INFO] python: 3.8.17
2023-09-01 13:51:43,851 [INFO] - python: 3.8.17
[2023-09-01 13:51:43 +0800] [68137] [INFO] platform: macOS-10.16-x86_64-i386-64bit
2023-09-01 13:51:43,851 [INFO] - platform: macOS-10.16-x86_64-i386-64bit
[2023-09-01 13:51:43 +0800] [68137] [INFO] packages: sanic-routing==23.6.0
2023-09-01 13:51:43,851 [INFO] - packages: sanic-routing==23.6.0
[2023-09-01 13:51:44 +0800] [68137] [ERROR] Experienced exception while trying to serve
Traceback (most recent call last):
  File "/Users/reuslujun/opt/anaconda3/envs/sanic/lib/python3.8/site-packages/sanic/server/socket.py", line 110, in configure_socket
    sock = bind_socket(
  File "/Users/reuslujun/opt/anaconda3/envs/sanic/lib/python3.8/site-packages/sanic/server/socket.py", line 33, in bind_socket
    sock.bind(location)
OSError: [Errno 48] Address already in use

During handling of the above exception, another exception occurred:

Traceback (most recent call last):
  File "/Users/reuslujun/opt/anaconda3/envs/sanic/lib/python3.8/site-packages/sanic/mixins/startup.py", line 781, in serve
    for sock in [
  File "/Users/reuslujun/opt/anaconda3/envs/sanic/lib/python3.8/site-packages/sanic/mixins/startup.py", line 782, in <listcomp>
    configure_socket(server_info.settings)
  File "/Users/reuslujun/opt/anaconda3/envs/sanic/lib/python3.8/site-packages/sanic/server/socket.py", line 125, in configure_socket
    raise error
sanic.exceptions.ServerError: Sanic server could not start: [Errno 48] Address already in use.

This may have happened if you are running Sanic in the global scope and not inside of a `if __name__ == "__main__"` block.

See more information: https://sanic.dev/en/guide/deployment/manager.html#how-sanic-server-starts-processes

2023-09-01 13:51:44,033 [ERROR] - Experienced exception while trying to serve
Traceback (most recent call last):
  File "/Users/reuslujun/opt/anaconda3/envs/sanic/lib/python3.8/site-packages/sanic/server/socket.py", line 110, in configure_socket
    sock = bind_socket(
  File "/Users/reuslujun/opt/anaconda3/envs/sanic/lib/python3.8/site-packages/sanic/server/socket.py", line 33, in bind_socket
    sock.bind(location)
OSError: [Errno 48] Address already in use

During handling of the above exception, another exception occurred:

Traceback (most recent call last):
  File "/Users/reuslujun/opt/anaconda3/envs/sanic/lib/python3.8/site-packages/sanic/mixins/startup.py", line 781, in serve
    for sock in [
  File "/Users/reuslujun/opt/anaconda3/envs/sanic/lib/python3.8/site-packages/sanic/mixins/startup.py", line 782, in <listcomp>
    configure_socket(server_info.settings)
  File "/Users/reuslujun/opt/anaconda3/envs/sanic/lib/python3.8/site-packages/sanic/server/socket.py", line 125, in configure_socket
    raise error
sanic.exceptions.ServerError: Sanic server could not start: [Errno 48] Address already in use.

This may have happened if you are running Sanic in the global scope and not inside of a `if __name__ == "__main__"` block.

See more information: https://sanic.dev/en/guide/deployment/manager.html#how-sanic-server-starts-processes

[2023-09-01 13:51:44 +0800] [68137] [INFO] Server Stopped
2023-09-01 13:51:44,034 [INFO] - Server Stopped
Traceback (most recent call last):
  File "/Users/reuslujun/opt/anaconda3/envs/sanic/lib/python3.8/site-packages/sanic/server/socket.py", line 110, in configure_socket
    sock = bind_socket(
  File "/Users/reuslujun/opt/anaconda3/envs/sanic/lib/python3.8/site-packages/sanic/server/socket.py", line 33, in bind_socket
    sock.bind(location)
OSError: [Errno 48] Address already in use

During handling of the above exception, another exception occurred:

Traceback (most recent call last):
  File "/Users/reuslujun/PycharmProjects/SanicStudy/test.py", line 24, in <module>
    app.run('localhost', 9999)
  File "/Users/reuslujun/opt/anaconda3/envs/sanic/lib/python3.8/site-packages/sanic/mixins/startup.py", line 215, in run
    serve(primary=self)  # type: ignore
  File "/Users/reuslujun/opt/anaconda3/envs/sanic/lib/python3.8/site-packages/sanic/mixins/startup.py", line 781, in serve
    for sock in [
  File "/Users/reuslujun/opt/anaconda3/envs/sanic/lib/python3.8/site-packages/sanic/mixins/startup.py", line 782, in <listcomp>
    configure_socket(server_info.settings)
  File "/Users/reuslujun/opt/anaconda3/envs/sanic/lib/python3.8/site-packages/sanic/server/socket.py", line 125, in configure_socket
    raise error
sanic.exceptions.ServerError: Sanic server could not start: [Errno 48] Address already in use.

This may have happened if you are running Sanic in the global scope and not inside of a `if __name__ == "__main__"` block.

See more information: https://sanic.dev/en/guide/deployment/manager.html#how-sanic-server-starts-processes

[2023-09-01 13:53:37 +0800] [70354] [INFO] Sanic v23.6.0
2023-09-01 13:53:37,135 [INFO] - Sanic v23.6.0
[2023-09-01 13:53:37 +0800] [70354] [INFO] Goin' Fast @ http://localhost:9999
2023-09-01 13:53:37,135 [INFO] - Goin' Fast @ http://localhost:9999
[2023-09-01 13:53:37 +0800] [70354] [INFO] mode: production, single worker
2023-09-01 13:53:37,135 [INFO] - mode: production, single worker
[2023-09-01 13:53:37 +0800] [70354] [INFO] server: sanic, HTTP/1.1
2023-09-01 13:53:37,135 [INFO] - server: sanic, HTTP/1.1
[2023-09-01 13:53:37 +0800] [70354] [INFO] python: 3.8.17
2023-09-01 13:53:37,135 [INFO] - python: 3.8.17
[2023-09-01 13:53:37 +0800] [70354] [INFO] platform: macOS-10.16-x86_64-i386-64bit
2023-09-01 13:53:37,135 [INFO] - platform: macOS-10.16-x86_64-i386-64bit
[2023-09-01 13:53:37 +0800] [70354] [INFO] packages: sanic-routing==23.6.0
2023-09-01 13:53:37,135 [INFO] - packages: sanic-routing==23.6.0
[2023-09-01 13:53:37 +0800] [70354] [ERROR] Experienced exception while trying to serve
Traceback (most recent call last):
  File "/Users/reuslujun/opt/anaconda3/envs/sanic/lib/python3.8/site-packages/sanic/server/socket.py", line 110, in configure_socket
    sock = bind_socket(
  File "/Users/reuslujun/opt/anaconda3/envs/sanic/lib/python3.8/site-packages/sanic/server/socket.py", line 33, in bind_socket
    sock.bind(location)
OSError: [Errno 48] Address already in use

During handling of the above exception, another exception occurred:

Traceback (most recent call last):
  File "/Users/reuslujun/opt/anaconda3/envs/sanic/lib/python3.8/site-packages/sanic/mixins/startup.py", line 781, in serve
    for sock in [
  File "/Users/reuslujun/opt/anaconda3/envs/sanic/lib/python3.8/site-packages/sanic/mixins/startup.py", line 782, in <listcomp>
    configure_socket(server_info.settings)
  File "/Users/reuslujun/opt/anaconda3/envs/sanic/lib/python3.8/site-packages/sanic/server/socket.py", line 125, in configure_socket
    raise error
sanic.exceptions.ServerError: Sanic server could not start: [Errno 48] Address already in use.

This may have happened if you are running Sanic in the global scope and not inside of a `if __name__ == "__main__"` block.

See more information: https://sanic.dev/en/guide/deployment/manager.html#how-sanic-server-starts-processes

2023-09-01 13:53:37,312 [ERROR] - Experienced exception while trying to serve
Traceback (most recent call last):
  File "/Users/reuslujun/opt/anaconda3/envs/sanic/lib/python3.8/site-packages/sanic/server/socket.py", line 110, in configure_socket
    sock = bind_socket(
  File "/Users/reuslujun/opt/anaconda3/envs/sanic/lib/python3.8/site-packages/sanic/server/socket.py", line 33, in bind_socket
    sock.bind(location)
OSError: [Errno 48] Address already in use

During handling of the above exception, another exception occurred:

Traceback (most recent call last):
  File "/Users/reuslujun/opt/anaconda3/envs/sanic/lib/python3.8/site-packages/sanic/mixins/startup.py", line 781, in serve
    for sock in [
  File "/Users/reuslujun/opt/anaconda3/envs/sanic/lib/python3.8/site-packages/sanic/mixins/startup.py", line 782, in <listcomp>
    configure_socket(server_info.settings)
  File "/Users/reuslujun/opt/anaconda3/envs/sanic/lib/python3.8/site-packages/sanic/server/socket.py", line 125, in configure_socket
    raise error
sanic.exceptions.ServerError: Sanic server could not start: [Errno 48] Address already in use.

This may have happened if you are running Sanic in the global scope and not inside of a `if __name__ == "__main__"` block.

See more information: https://sanic.dev/en/guide/deployment/manager.html#how-sanic-server-starts-processes

[2023-09-01 13:53:37 +0800] [70354] [INFO] Server Stopped
2023-09-01 13:53:37,313 [INFO] - Server Stopped
Traceback (most recent call last):
  File "/Users/reuslujun/opt/anaconda3/envs/sanic/lib/python3.8/site-packages/sanic/server/socket.py", line 110, in configure_socket
    sock = bind_socket(
  File "/Users/reuslujun/opt/anaconda3/envs/sanic/lib/python3.8/site-packages/sanic/server/socket.py", line 33, in bind_socket
    sock.bind(location)
OSError: [Errno 48] Address already in use

During handling of the above exception, another exception occurred:

Traceback (most recent call last):
  File "/Users/reuslujun/PycharmProjects/SanicStudy/test.py", line 24, in <module>
    app.run('localhost', 9999)
  File "/Users/reuslujun/opt/anaconda3/envs/sanic/lib/python3.8/site-packages/sanic/mixins/startup.py", line 215, in run
    serve(primary=self)  # type: ignore
  File "/Users/reuslujun/opt/anaconda3/envs/sanic/lib/python3.8/site-packages/sanic/mixins/startup.py", line 781, in serve
    for sock in [
  File "/Users/reuslujun/opt/anaconda3/envs/sanic/lib/python3.8/site-packages/sanic/mixins/startup.py", line 782, in <listcomp>
    configure_socket(server_info.settings)
  File "/Users/reuslujun/opt/anaconda3/envs/sanic/lib/python3.8/site-packages/sanic/server/socket.py", line 125, in configure_socket
    raise error
sanic.exceptions.ServerError: Sanic server could not start: [Errno 48] Address already in use.

This may have happened if you are running Sanic in the global scope and not inside of a `if __name__ == "__main__"` block.

See more information: https://sanic.dev/en/guide/deployment/manager.html#how-sanic-server-starts-processes

[2023-09-01 13:54:17 +0800] [71196] [INFO] Sanic v23.6.0
2023-09-01 13:54:17,901 [INFO] - Sanic v23.6.0
[2023-09-01 13:54:17 +0800] [71196] [INFO] Goin' Fast @ http://localhost:9999
2023-09-01 13:54:17,902 [INFO] - Goin' Fast @ http://localhost:9999
[2023-09-01 13:54:17 +0800] [71196] [INFO] mode: production, single worker
2023-09-01 13:54:17,902 [INFO] - mode: production, single worker
[2023-09-01 13:54:17 +0800] [71196] [INFO] server: sanic, HTTP/1.1
2023-09-01 13:54:17,902 [INFO] - server: sanic, HTTP/1.1
[2023-09-01 13:54:17 +0800] [71196] [INFO] python: 3.8.17
2023-09-01 13:54:17,902 [INFO] - python: 3.8.17
[2023-09-01 13:54:17 +0800] [71196] [INFO] platform: macOS-10.16-x86_64-i386-64bit
2023-09-01 13:54:17,902 [INFO] - platform: macOS-10.16-x86_64-i386-64bit
[2023-09-01 13:54:17 +0800] [71196] [INFO] packages: sanic-routing==23.6.0
2023-09-01 13:54:17,902 [INFO] - packages: sanic-routing==23.6.0
[2023-09-01 13:54:18 +0800] [71196] [ERROR] Experienced exception while trying to serve
Traceback (most recent call last):
  File "/Users/reuslujun/opt/anaconda3/envs/sanic/lib/python3.8/site-packages/sanic/server/socket.py", line 110, in configure_socket
    sock = bind_socket(
  File "/Users/reuslujun/opt/anaconda3/envs/sanic/lib/python3.8/site-packages/sanic/server/socket.py", line 33, in bind_socket
    sock.bind(location)
OSError: [Errno 48] Address already in use

During handling of the above exception, another exception occurred:

Traceback (most recent call last):
  File "/Users/reuslujun/opt/anaconda3/envs/sanic/lib/python3.8/site-packages/sanic/mixins/startup.py", line 781, in serve
    for sock in [
  File "/Users/reuslujun/opt/anaconda3/envs/sanic/lib/python3.8/site-packages/sanic/mixins/startup.py", line 782, in <listcomp>
    configure_socket(server_info.settings)
  File "/Users/reuslujun/opt/anaconda3/envs/sanic/lib/python3.8/site-packages/sanic/server/socket.py", line 125, in configure_socket
    raise error
sanic.exceptions.ServerError: Sanic server could not start: [Errno 48] Address already in use.

This may have happened if you are running Sanic in the global scope and not inside of a `if __name__ == "__main__"` block.

See more information: https://sanic.dev/en/guide/deployment/manager.html#how-sanic-server-starts-processes

2023-09-01 13:54:18,080 [ERROR] - Experienced exception while trying to serve
Traceback (most recent call last):
  File "/Users/reuslujun/opt/anaconda3/envs/sanic/lib/python3.8/site-packages/sanic/server/socket.py", line 110, in configure_socket
    sock = bind_socket(
  File "/Users/reuslujun/opt/anaconda3/envs/sanic/lib/python3.8/site-packages/sanic/server/socket.py", line 33, in bind_socket
    sock.bind(location)
OSError: [Errno 48] Address already in use

During handling of the above exception, another exception occurred:

Traceback (most recent call last):
  File "/Users/reuslujun/opt/anaconda3/envs/sanic/lib/python3.8/site-packages/sanic/mixins/startup.py", line 781, in serve
    for sock in [
  File "/Users/reuslujun/opt/anaconda3/envs/sanic/lib/python3.8/site-packages/sanic/mixins/startup.py", line 782, in <listcomp>
    configure_socket(server_info.settings)
  File "/Users/reuslujun/opt/anaconda3/envs/sanic/lib/python3.8/site-packages/sanic/server/socket.py", line 125, in configure_socket
    raise error
sanic.exceptions.ServerError: Sanic server could not start: [Errno 48] Address already in use.

This may have happened if you are running Sanic in the global scope and not inside of a `if __name__ == "__main__"` block.

See more information: https://sanic.dev/en/guide/deployment/manager.html#how-sanic-server-starts-processes

[2023-09-01 13:54:18 +0800] [71196] [INFO] Server Stopped
2023-09-01 13:54:18,081 [INFO] - Server Stopped
Traceback (most recent call last):
  File "/Users/reuslujun/opt/anaconda3/envs/sanic/lib/python3.8/site-packages/sanic/server/socket.py", line 110, in configure_socket
    sock = bind_socket(
  File "/Users/reuslujun/opt/anaconda3/envs/sanic/lib/python3.8/site-packages/sanic/server/socket.py", line 33, in bind_socket
    sock.bind(location)
OSError: [Errno 48] Address already in use

During handling of the above exception, another exception occurred:

Traceback (most recent call last):
  File "/Users/reuslujun/PycharmProjects/SanicStudy/test.py", line 24, in <module>
    app.run('localhost', 9999)
  File "/Users/reuslujun/opt/anaconda3/envs/sanic/lib/python3.8/site-packages/sanic/mixins/startup.py", line 215, in run
    serve(primary=self)  # type: ignore
  File "/Users/reuslujun/opt/anaconda3/envs/sanic/lib/python3.8/site-packages/sanic/mixins/startup.py", line 781, in serve
    for sock in [
  File "/Users/reuslujun/opt/anaconda3/envs/sanic/lib/python3.8/site-packages/sanic/mixins/startup.py", line 782, in <listcomp>
    configure_socket(server_info.settings)
  File "/Users/reuslujun/opt/anaconda3/envs/sanic/lib/python3.8/site-packages/sanic/server/socket.py", line 125, in configure_socket
    raise error
sanic.exceptions.ServerError: Sanic server could not start: [Errno 48] Address already in use.

This may have happened if you are running Sanic in the global scope and not inside of a `if __name__ == "__main__"` block.

See more information: https://sanic.dev/en/guide/deployment/manager.html#how-sanic-server-starts-processes

[2023-09-01 14:00:22 +0800] [78662] [INFO] Sanic v23.6.0
2023-09-01 14:00:22,973 [INFO] - Sanic v23.6.0
[2023-09-01 14:00:22 +0800] [78662] [INFO] Goin' Fast @ http://localhost:9999
2023-09-01 14:00:22,973 [INFO] - Goin' Fast @ http://localhost:9999
[2023-09-01 14:00:22 +0800] [78662] [INFO] mode: production, single worker
2023-09-01 14:00:22,973 [INFO] - mode: production, single worker
[2023-09-01 14:00:22 +0800] [78662] [INFO] server: sanic, HTTP/1.1
2023-09-01 14:00:22,973 [INFO] - server: sanic, HTTP/1.1
[2023-09-01 14:00:22 +0800] [78662] [INFO] python: 3.8.17
2023-09-01 14:00:22,973 [INFO] - python: 3.8.17
[2023-09-01 14:00:22 +0800] [78662] [INFO] platform: macOS-10.16-x86_64-i386-64bit
2023-09-01 14:00:22,973 [INFO] - platform: macOS-10.16-x86_64-i386-64bit
[2023-09-01 14:00:22 +0800] [78662] [INFO] packages: sanic-routing==23.6.0
2023-09-01 14:00:22,973 [INFO] - packages: sanic-routing==23.6.0
[2023-09-01 14:00:23 +0800] [78662] [ERROR] Experienced exception while trying to serve
Traceback (most recent call last):
  File "/Users/reuslujun/opt/anaconda3/envs/sanic/lib/python3.8/site-packages/sanic/server/socket.py", line 110, in configure_socket
    sock = bind_socket(
  File "/Users/reuslujun/opt/anaconda3/envs/sanic/lib/python3.8/site-packages/sanic/server/socket.py", line 33, in bind_socket
    sock.bind(location)
OSError: [Errno 48] Address already in use

During handling of the above exception, another exception occurred:

Traceback (most recent call last):
  File "/Users/reuslujun/opt/anaconda3/envs/sanic/lib/python3.8/site-packages/sanic/mixins/startup.py", line 781, in serve
    for sock in [
  File "/Users/reuslujun/opt/anaconda3/envs/sanic/lib/python3.8/site-packages/sanic/mixins/startup.py", line 782, in <listcomp>
    configure_socket(server_info.settings)
  File "/Users/reuslujun/opt/anaconda3/envs/sanic/lib/python3.8/site-packages/sanic/server/socket.py", line 125, in configure_socket
    raise error
sanic.exceptions.ServerError: Sanic server could not start: [Errno 48] Address already in use.

This may have happened if you are running Sanic in the global scope and not inside of a `if __name__ == "__main__"` block.

See more information: https://sanic.dev/en/guide/deployment/manager.html#how-sanic-server-starts-processes

2023-09-01 14:00:23,159 [ERROR] - Experienced exception while trying to serve
Traceback (most recent call last):
  File "/Users/reuslujun/opt/anaconda3/envs/sanic/lib/python3.8/site-packages/sanic/server/socket.py", line 110, in configure_socket
    sock = bind_socket(
  File "/Users/reuslujun/opt/anaconda3/envs/sanic/lib/python3.8/site-packages/sanic/server/socket.py", line 33, in bind_socket
    sock.bind(location)
OSError: [Errno 48] Address already in use

During handling of the above exception, another exception occurred:

Traceback (most recent call last):
  File "/Users/reuslujun/opt/anaconda3/envs/sanic/lib/python3.8/site-packages/sanic/mixins/startup.py", line 781, in serve
    for sock in [
  File "/Users/reuslujun/opt/anaconda3/envs/sanic/lib/python3.8/site-packages/sanic/mixins/startup.py", line 782, in <listcomp>
    configure_socket(server_info.settings)
  File "/Users/reuslujun/opt/anaconda3/envs/sanic/lib/python3.8/site-packages/sanic/server/socket.py", line 125, in configure_socket
    raise error
sanic.exceptions.ServerError: Sanic server could not start: [Errno 48] Address already in use.

This may have happened if you are running Sanic in the global scope and not inside of a `if __name__ == "__main__"` block.

See more information: https://sanic.dev/en/guide/deployment/manager.html#how-sanic-server-starts-processes

[2023-09-01 14:00:23 +0800] [78662] [INFO] Server Stopped
2023-09-01 14:00:23,160 [INFO] - Server Stopped
Traceback (most recent call last):
  File "/Users/reuslujun/opt/anaconda3/envs/sanic/lib/python3.8/site-packages/sanic/server/socket.py", line 110, in configure_socket
    sock = bind_socket(
  File "/Users/reuslujun/opt/anaconda3/envs/sanic/lib/python3.8/site-packages/sanic/server/socket.py", line 33, in bind_socket
    sock.bind(location)
OSError: [Errno 48] Address already in use

During handling of the above exception, another exception occurred:

Traceback (most recent call last):
  File "/Users/reuslujun/PycharmProjects/SanicStudy/test.py", line 24, in <module>
    app.run('localhost', 9999)
  File "/Users/reuslujun/opt/anaconda3/envs/sanic/lib/python3.8/site-packages/sanic/mixins/startup.py", line 215, in run
    serve(primary=self)  # type: ignore
  File "/Users/reuslujun/opt/anaconda3/envs/sanic/lib/python3.8/site-packages/sanic/mixins/startup.py", line 781, in serve
    for sock in [
  File "/Users/reuslujun/opt/anaconda3/envs/sanic/lib/python3.8/site-packages/sanic/mixins/startup.py", line 782, in <listcomp>
    configure_socket(server_info.settings)
  File "/Users/reuslujun/opt/anaconda3/envs/sanic/lib/python3.8/site-packages/sanic/server/socket.py", line 125, in configure_socket
    raise error
sanic.exceptions.ServerError: Sanic server could not start: [Errno 48] Address already in use.

This may have happened if you are running Sanic in the global scope and not inside of a `if __name__ == "__main__"` block.

See more information: https://sanic.dev/en/guide/deployment/manager.html#how-sanic-server-starts-processes

[2023-09-01 14:04:46 +0800] [84263] [INFO] Sanic v23.6.0
2023-09-01 14:04:46,395 [INFO] - Sanic v23.6.0
[2023-09-01 14:04:46 +0800] [84263] [INFO] Goin' Fast @ http://localhost:9999
2023-09-01 14:04:46,395 [INFO] - Goin' Fast @ http://localhost:9999
[2023-09-01 14:04:46 +0800] [84263] [INFO] mode: production, single worker
2023-09-01 14:04:46,395 [INFO] - mode: production, single worker
[2023-09-01 14:04:46 +0800] [84263] [INFO] server: sanic, HTTP/1.1
2023-09-01 14:04:46,395 [INFO] - server: sanic, HTTP/1.1
[2023-09-01 14:04:46 +0800] [84263] [INFO] python: 3.8.17
2023-09-01 14:04:46,395 [INFO] - python: 3.8.17
[2023-09-01 14:04:46 +0800] [84263] [INFO] platform: macOS-10.16-x86_64-i386-64bit
2023-09-01 14:04:46,395 [INFO] - platform: macOS-10.16-x86_64-i386-64bit
[2023-09-01 14:04:46 +0800] [84263] [INFO] packages: sanic-routing==23.6.0
2023-09-01 14:04:46,395 [INFO] - packages: sanic-routing==23.6.0
[2023-09-01 14:04:46 +0800] [84263] [ERROR] Experienced exception while trying to serve
Traceback (most recent call last):
  File "/Users/reuslujun/opt/anaconda3/envs/sanic/lib/python3.8/site-packages/sanic/server/socket.py", line 110, in configure_socket
    sock = bind_socket(
  File "/Users/reuslujun/opt/anaconda3/envs/sanic/lib/python3.8/site-packages/sanic/server/socket.py", line 33, in bind_socket
    sock.bind(location)
OSError: [Errno 48] Address already in use

During handling of the above exception, another exception occurred:

Traceback (most recent call last):
  File "/Users/reuslujun/opt/anaconda3/envs/sanic/lib/python3.8/site-packages/sanic/mixins/startup.py", line 781, in serve
    for sock in [
  File "/Users/reuslujun/opt/anaconda3/envs/sanic/lib/python3.8/site-packages/sanic/mixins/startup.py", line 782, in <listcomp>
    configure_socket(server_info.settings)
  File "/Users/reuslujun/opt/anaconda3/envs/sanic/lib/python3.8/site-packages/sanic/server/socket.py", line 125, in configure_socket
    raise error
sanic.exceptions.ServerError: Sanic server could not start: [Errno 48] Address already in use.

This may have happened if you are running Sanic in the global scope and not inside of a `if __name__ == "__main__"` block.

See more information: https://sanic.dev/en/guide/deployment/manager.html#how-sanic-server-starts-processes

2023-09-01 14:04:46,578 [ERROR] - Experienced exception while trying to serve
Traceback (most recent call last):
  File "/Users/reuslujun/opt/anaconda3/envs/sanic/lib/python3.8/site-packages/sanic/server/socket.py", line 110, in configure_socket
    sock = bind_socket(
  File "/Users/reuslujun/opt/anaconda3/envs/sanic/lib/python3.8/site-packages/sanic/server/socket.py", line 33, in bind_socket
    sock.bind(location)
OSError: [Errno 48] Address already in use

During handling of the above exception, another exception occurred:

Traceback (most recent call last):
  File "/Users/reuslujun/opt/anaconda3/envs/sanic/lib/python3.8/site-packages/sanic/mixins/startup.py", line 781, in serve
    for sock in [
  File "/Users/reuslujun/opt/anaconda3/envs/sanic/lib/python3.8/site-packages/sanic/mixins/startup.py", line 782, in <listcomp>
    configure_socket(server_info.settings)
  File "/Users/reuslujun/opt/anaconda3/envs/sanic/lib/python3.8/site-packages/sanic/server/socket.py", line 125, in configure_socket
    raise error
sanic.exceptions.ServerError: Sanic server could not start: [Errno 48] Address already in use.

This may have happened if you are running Sanic in the global scope and not inside of a `if __name__ == "__main__"` block.

See more information: https://sanic.dev/en/guide/deployment/manager.html#how-sanic-server-starts-processes

[2023-09-01 14:04:46 +0800] [84263] [INFO] Server Stopped
2023-09-01 14:04:46,579 [INFO] - Server Stopped
Traceback (most recent call last):
  File "/Users/reuslujun/opt/anaconda3/envs/sanic/lib/python3.8/site-packages/sanic/server/socket.py", line 110, in configure_socket
    sock = bind_socket(
  File "/Users/reuslujun/opt/anaconda3/envs/sanic/lib/python3.8/site-packages/sanic/server/socket.py", line 33, in bind_socket
    sock.bind(location)
OSError: [Errno 48] Address already in use

During handling of the above exception, another exception occurred:

Traceback (most recent call last):
  File "/Users/reuslujun/PycharmProjects/SanicStudy/test.py", line 24, in <module>
    app.run('localhost', 9999)
  File "/Users/reuslujun/opt/anaconda3/envs/sanic/lib/python3.8/site-packages/sanic/mixins/startup.py", line 215, in run
    serve(primary=self)  # type: ignore
  File "/Users/reuslujun/opt/anaconda3/envs/sanic/lib/python3.8/site-packages/sanic/mixins/startup.py", line 781, in serve
    for sock in [
  File "/Users/reuslujun/opt/anaconda3/envs/sanic/lib/python3.8/site-packages/sanic/mixins/startup.py", line 782, in <listcomp>
    configure_socket(server_info.settings)
  File "/Users/reuslujun/opt/anaconda3/envs/sanic/lib/python3.8/site-packages/sanic/server/socket.py", line 125, in configure_socket
    raise error
sanic.exceptions.ServerError: Sanic server could not start: [Errno 48] Address already in use.

This may have happened if you are running Sanic in the global scope and not inside of a `if __name__ == "__main__"` block.

See more information: https://sanic.dev/en/guide/deployment/manager.html#how-sanic-server-starts-processes

[2023-09-01 14:05:50 +0800] [17559] [INFO] Received signal SIGTERM. Shutting down.
2023-09-01 14:05:50,524 [INFO] - Received signal SIGTERM. Shutting down.
我在print
[2023-09-01 14:05:50 +0800] [17567] [INFO] Stopping worker [17567]
2023-09-01 14:05:50,528 [INFO] - Stopping worker [17567]
[2023-09-01 14:05:50 +0800] [17559] [ERROR] Experienced exception while trying to serve
Traceback (most recent call last):
  File "/Users/reuslujun/opt/anaconda3/envs/sanic/lib/python3.8/site-packages/sanic/mixins/startup.py", line 880, in serve
    manager.run()
  File "/Users/reuslujun/opt/anaconda3/envs/sanic/lib/python3.8/site-packages/sanic/worker/manager.py", line 122, in run
    self.monitor()
  File "/Users/reuslujun/opt/anaconda3/envs/sanic/lib/python3.8/site-packages/sanic/worker/manager.py", line 186, in monitor
    if self.monitor_subscriber.poll(0.1):
  File "/Users/reuslujun/opt/anaconda3/envs/sanic/lib/python3.8/multiprocessing/connection.py", line 257, in poll
    return self._poll(timeout)
  File "/Users/reuslujun/opt/anaconda3/envs/sanic/lib/python3.8/multiprocessing/connection.py", line 424, in _poll
    r = wait([self], timeout)
  File "/Users/reuslujun/opt/anaconda3/envs/sanic/lib/python3.8/multiprocessing/connection.py", line 931, in wait
    ready = selector.select(timeout)
  File "/Users/reuslujun/opt/anaconda3/envs/sanic/lib/python3.8/selectors.py", line 415, in select
    fd_event_list = self._selector.poll(timeout)
  File "/Users/reuslujun/opt/anaconda3/envs/sanic/lib/python3.8/site-packages/sanic/worker/manager.py", line 293, in shutdown_signal
    self.shutdown()
  File "/Users/reuslujun/opt/anaconda3/envs/sanic/lib/python3.8/site-packages/sanic/worker/manager.py", line 298, in shutdown
    process.terminate()
  File "/Users/reuslujun/opt/anaconda3/envs/sanic/lib/python3.8/site-packages/sanic/worker/process.py", line 77, in terminate
    self.set_state(ProcessState.TERMINATED, force=True)
  File "/Users/reuslujun/opt/anaconda3/envs/sanic/lib/python3.8/site-packages/sanic/worker/process.py", line 41, in set_state
    **self.worker_state[self.name],
  File "<string>", line 2, in __getitem__
  File "/Users/reuslujun/opt/anaconda3/envs/sanic/lib/python3.8/multiprocessing/managers.py", line 835, in _callmethod
    kind, result = conn.recv()
  File "/Users/reuslujun/opt/anaconda3/envs/sanic/lib/python3.8/multiprocessing/connection.py", line 250, in recv
    buf = self._recv_bytes()
  File "/Users/reuslujun/opt/anaconda3/envs/sanic/lib/python3.8/multiprocessing/connection.py", line 414, in _recv_bytes
    buf = self._recv(4)
  File "/Users/reuslujun/opt/anaconda3/envs/sanic/lib/python3.8/multiprocessing/connection.py", line 383, in _recv
    raise EOFError
EOFError
2023-09-01 14:05:50,531 [ERROR] - Experienced exception while trying to serve
Traceback (most recent call last):
  File "/Users/reuslujun/opt/anaconda3/envs/sanic/lib/python3.8/site-packages/sanic/mixins/startup.py", line 880, in serve
    manager.run()
  File "/Users/reuslujun/opt/anaconda3/envs/sanic/lib/python3.8/site-packages/sanic/worker/manager.py", line 122, in run
    self.monitor()
  File "/Users/reuslujun/opt/anaconda3/envs/sanic/lib/python3.8/site-packages/sanic/worker/manager.py", line 186, in monitor
    if self.monitor_subscriber.poll(0.1):
  File "/Users/reuslujun/opt/anaconda3/envs/sanic/lib/python3.8/multiprocessing/connection.py", line 257, in poll
    return self._poll(timeout)
  File "/Users/reuslujun/opt/anaconda3/envs/sanic/lib/python3.8/multiprocessing/connection.py", line 424, in _poll
    r = wait([self], timeout)
  File "/Users/reuslujun/opt/anaconda3/envs/sanic/lib/python3.8/multiprocessing/connection.py", line 931, in wait
    ready = selector.select(timeout)
  File "/Users/reuslujun/opt/anaconda3/envs/sanic/lib/python3.8/selectors.py", line 415, in select
    fd_event_list = self._selector.poll(timeout)
  File "/Users/reuslujun/opt/anaconda3/envs/sanic/lib/python3.8/site-packages/sanic/worker/manager.py", line 293, in shutdown_signal
    self.shutdown()
  File "/Users/reuslujun/opt/anaconda3/envs/sanic/lib/python3.8/site-packages/sanic/worker/manager.py", line 298, in shutdown
    process.terminate()
  File "/Users/reuslujun/opt/anaconda3/envs/sanic/lib/python3.8/site-packages/sanic/worker/process.py", line 77, in terminate
    self.set_state(ProcessState.TERMINATED, force=True)
  File "/Users/reuslujun/opt/anaconda3/envs/sanic/lib/python3.8/site-packages/sanic/worker/process.py", line 41, in set_state
    **self.worker_state[self.name],
  File "<string>", line 2, in __getitem__
  File "/Users/reuslujun/opt/anaconda3/envs/sanic/lib/python3.8/multiprocessing/managers.py", line 835, in _callmethod
    kind, result = conn.recv()
  File "/Users/reuslujun/opt/anaconda3/envs/sanic/lib/python3.8/multiprocessing/connection.py", line 250, in recv
    buf = self._recv_bytes()
  File "/Users/reuslujun/opt/anaconda3/envs/sanic/lib/python3.8/multiprocessing/connection.py", line 414, in _recv_bytes
    buf = self._recv(4)
  File "/Users/reuslujun/opt/anaconda3/envs/sanic/lib/python3.8/multiprocessing/connection.py", line 383, in _recv
    raise EOFError
EOFError
[2023-09-01 14:05:50 +0800] [17559] [INFO] Server Stopped
2023-09-01 14:05:50,535 [INFO] - Server Stopped
Traceback (most recent call last):
  File "/Users/reuslujun/PycharmProjects/SanicStudy/test.py", line 24, in <module>
    app.run('localhost', 9999)
  File "/Users/reuslujun/opt/anaconda3/envs/sanic/lib/python3.8/site-packages/sanic/mixins/startup.py", line 215, in run
    serve(primary=self)  # type: ignore
  File "/Users/reuslujun/opt/anaconda3/envs/sanic/lib/python3.8/site-packages/sanic/mixins/startup.py", line 880, in serve
    manager.run()
  File "/Users/reuslujun/opt/anaconda3/envs/sanic/lib/python3.8/site-packages/sanic/worker/manager.py", line 122, in run
    self.monitor()
  File "/Users/reuslujun/opt/anaconda3/envs/sanic/lib/python3.8/site-packages/sanic/worker/manager.py", line 186, in monitor
    if self.monitor_subscriber.poll(0.1):
  File "/Users/reuslujun/opt/anaconda3/envs/sanic/lib/python3.8/multiprocessing/connection.py", line 257, in poll
    return self._poll(timeout)
  File "/Users/reuslujun/opt/anaconda3/envs/sanic/lib/python3.8/multiprocessing/connection.py", line 424, in _poll
    r = wait([self], timeout)
  File "/Users/reuslujun/opt/anaconda3/envs/sanic/lib/python3.8/multiprocessing/connection.py", line 931, in wait
    ready = selector.select(timeout)
  File "/Users/reuslujun/opt/anaconda3/envs/sanic/lib/python3.8/selectors.py", line 415, in select
    fd_event_list = self._selector.poll(timeout)
  File "/Users/reuslujun/opt/anaconda3/envs/sanic/lib/python3.8/site-packages/sanic/worker/manager.py", line 293, in shutdown_signal
    self.shutdown()
  File "/Users/reuslujun/opt/anaconda3/envs/sanic/lib/python3.8/site-packages/sanic/worker/manager.py", line 298, in shutdown
    process.terminate()
  File "/Users/reuslujun/opt/anaconda3/envs/sanic/lib/python3.8/site-packages/sanic/worker/process.py", line 77, in terminate
    self.set_state(ProcessState.TERMINATED, force=True)
  File "/Users/reuslujun/opt/anaconda3/envs/sanic/lib/python3.8/site-packages/sanic/worker/process.py", line 41, in set_state
    **self.worker_state[self.name],
  File "<string>", line 2, in __getitem__
  File "/Users/reuslujun/opt/anaconda3/envs/sanic/lib/python3.8/multiprocessing/managers.py", line 835, in _callmethod
    kind, result = conn.recv()
  File "/Users/reuslujun/opt/anaconda3/envs/sanic/lib/python3.8/multiprocessing/connection.py", line 250, in recv
    buf = self._recv_bytes()
  File "/Users/reuslujun/opt/anaconda3/envs/sanic/lib/python3.8/multiprocessing/connection.py", line 414, in _recv_bytes
    buf = self._recv(4)
  File "/Users/reuslujun/opt/anaconda3/envs/sanic/lib/python3.8/multiprocessing/connection.py", line 383, in _recv
    raise EOFError
EOFError
[2023-09-01 14:08:37 +0800] [88898] [INFO] Sanic v23.6.0
2023-09-01 14:08:37,333 [INFO] - Sanic v23.6.0
[2023-09-01 14:08:37 +0800] [88898] [INFO] Goin' Fast @ http://localhost:9999
2023-09-01 14:08:37,333 [INFO] - Goin' Fast @ http://localhost:9999
[2023-09-01 14:08:37 +0800] [88898] [INFO] mode: production, single worker
2023-09-01 14:08:37,333 [INFO] - mode: production, single worker
[2023-09-01 14:08:37 +0800] [88898] [INFO] server: sanic, HTTP/1.1
2023-09-01 14:08:37,333 [INFO] - server: sanic, HTTP/1.1
[2023-09-01 14:08:37 +0800] [88898] [INFO] python: 3.8.17
2023-09-01 14:08:37,333 [INFO] - python: 3.8.17
[2023-09-01 14:08:37 +0800] [88898] [INFO] platform: macOS-10.16-x86_64-i386-64bit
2023-09-01 14:08:37,333 [INFO] - platform: macOS-10.16-x86_64-i386-64bit
[2023-09-01 14:08:37 +0800] [88898] [INFO] packages: sanic-routing==23.6.0
2023-09-01 14:08:37,333 [INFO] - packages: sanic-routing==23.6.0
[2023-09-01 14:08:37 +0800] [88909] [INFO] Starting worker [88909]
2023-09-01 14:08:37,726 [INFO] - Starting worker [88909]
[2023-09-01 14:09:31 +0800] [90150] [INFO] Sanic v23.6.0
2023-09-01 14:09:31,443 [INFO] - Sanic v23.6.0
[2023-09-01 14:09:31 +0800] [90150] [INFO] Goin' Fast @ http://localhost:9999
2023-09-01 14:09:31,444 [INFO] - Goin' Fast @ http://localhost:9999
[2023-09-01 14:09:31 +0800] [90150] [INFO] mode: production, single worker
2023-09-01 14:09:31,444 [INFO] - mode: production, single worker
[2023-09-01 14:09:31 +0800] [90150] [INFO] server: sanic, HTTP/1.1
2023-09-01 14:09:31,444 [INFO] - server: sanic, HTTP/1.1
[2023-09-01 14:09:31 +0800] [90150] [INFO] python: 3.8.17
2023-09-01 14:09:31,444 [INFO] - python: 3.8.17
[2023-09-01 14:09:31 +0800] [90150] [INFO] platform: macOS-10.16-x86_64-i386-64bit
2023-09-01 14:09:31,444 [INFO] - platform: macOS-10.16-x86_64-i386-64bit
[2023-09-01 14:09:31 +0800] [90150] [INFO] packages: sanic-routing==23.6.0
2023-09-01 14:09:31,444 [INFO] - packages: sanic-routing==23.6.0
[2023-09-01 14:09:31 +0800] [90150] [ERROR] Experienced exception while trying to serve
Traceback (most recent call last):
  File "/Users/reuslujun/opt/anaconda3/envs/sanic/lib/python3.8/site-packages/sanic/server/socket.py", line 110, in configure_socket
    sock = bind_socket(
  File "/Users/reuslujun/opt/anaconda3/envs/sanic/lib/python3.8/site-packages/sanic/server/socket.py", line 33, in bind_socket
    sock.bind(location)
OSError: [Errno 48] Address already in use

During handling of the above exception, another exception occurred:

Traceback (most recent call last):
  File "/Users/reuslujun/opt/anaconda3/envs/sanic/lib/python3.8/site-packages/sanic/mixins/startup.py", line 781, in serve
    for sock in [
  File "/Users/reuslujun/opt/anaconda3/envs/sanic/lib/python3.8/site-packages/sanic/mixins/startup.py", line 782, in <listcomp>
    configure_socket(server_info.settings)
  File "/Users/reuslujun/opt/anaconda3/envs/sanic/lib/python3.8/site-packages/sanic/server/socket.py", line 125, in configure_socket
    raise error
sanic.exceptions.ServerError: Sanic server could not start: [Errno 48] Address already in use.

This may have happened if you are running Sanic in the global scope and not inside of a `if __name__ == "__main__"` block.

See more information: https://sanic.dev/en/guide/deployment/manager.html#how-sanic-server-starts-processes

2023-09-01 14:09:31,626 [ERROR] - Experienced exception while trying to serve
Traceback (most recent call last):
  File "/Users/reuslujun/opt/anaconda3/envs/sanic/lib/python3.8/site-packages/sanic/server/socket.py", line 110, in configure_socket
    sock = bind_socket(
  File "/Users/reuslujun/opt/anaconda3/envs/sanic/lib/python3.8/site-packages/sanic/server/socket.py", line 33, in bind_socket
    sock.bind(location)
OSError: [Errno 48] Address already in use

During handling of the above exception, another exception occurred:

Traceback (most recent call last):
  File "/Users/reuslujun/opt/anaconda3/envs/sanic/lib/python3.8/site-packages/sanic/mixins/startup.py", line 781, in serve
    for sock in [
  File "/Users/reuslujun/opt/anaconda3/envs/sanic/lib/python3.8/site-packages/sanic/mixins/startup.py", line 782, in <listcomp>
    configure_socket(server_info.settings)
  File "/Users/reuslujun/opt/anaconda3/envs/sanic/lib/python3.8/site-packages/sanic/server/socket.py", line 125, in configure_socket
    raise error
sanic.exceptions.ServerError: Sanic server could not start: [Errno 48] Address already in use.

This may have happened if you are running Sanic in the global scope and not inside of a `if __name__ == "__main__"` block.

See more information: https://sanic.dev/en/guide/deployment/manager.html#how-sanic-server-starts-processes

[2023-09-01 14:09:31 +0800] [90150] [INFO] Server Stopped
2023-09-01 14:09:31,627 [INFO] - Server Stopped
Traceback (most recent call last):
  File "/Users/reuslujun/opt/anaconda3/envs/sanic/lib/python3.8/site-packages/sanic/server/socket.py", line 110, in configure_socket
    sock = bind_socket(
  File "/Users/reuslujun/opt/anaconda3/envs/sanic/lib/python3.8/site-packages/sanic/server/socket.py", line 33, in bind_socket
    sock.bind(location)
OSError: [Errno 48] Address already in use

During handling of the above exception, another exception occurred:

Traceback (most recent call last):
  File "/Users/reuslujun/PycharmProjects/SanicStudy/test.py", line 24, in <module>
    app.run('localhost', 9999)
  File "/Users/reuslujun/opt/anaconda3/envs/sanic/lib/python3.8/site-packages/sanic/mixins/startup.py", line 215, in run
    serve(primary=self)  # type: ignore
  File "/Users/reuslujun/opt/anaconda3/envs/sanic/lib/python3.8/site-packages/sanic/mixins/startup.py", line 781, in serve
    for sock in [
  File "/Users/reuslujun/opt/anaconda3/envs/sanic/lib/python3.8/site-packages/sanic/mixins/startup.py", line 782, in <listcomp>
    configure_socket(server_info.settings)
  File "/Users/reuslujun/opt/anaconda3/envs/sanic/lib/python3.8/site-packages/sanic/server/socket.py", line 125, in configure_socket
    raise error
sanic.exceptions.ServerError: Sanic server could not start: [Errno 48] Address already in use.

This may have happened if you are running Sanic in the global scope and not inside of a `if __name__ == "__main__"` block.

See more information: https://sanic.dev/en/guide/deployment/manager.html#how-sanic-server-starts-processes

[2023-09-01 14:09:38 +0800] [88898] [INFO] Received signal SIGTERM. Shutting down.
2023-09-01 14:09:38,950 [INFO] - Received signal SIGTERM. Shutting down.
[2023-09-01 14:09:38 +0800] [88909] [INFO] Stopping worker [88909]
2023-09-01 14:09:38,951 [INFO] - Stopping worker [88909]
[2023-09-01 14:09:38 +0800] [88898] [ERROR] Experienced exception while trying to serve
Traceback (most recent call last):
  File "/Users/reuslujun/opt/anaconda3/envs/sanic/lib/python3.8/site-packages/sanic/mixins/startup.py", line 880, in serve
    manager.run()
  File "/Users/reuslujun/opt/anaconda3/envs/sanic/lib/python3.8/site-packages/sanic/worker/manager.py", line 122, in run
    self.monitor()
  File "/Users/reuslujun/opt/anaconda3/envs/sanic/lib/python3.8/site-packages/sanic/worker/manager.py", line 186, in monitor
    if self.monitor_subscriber.poll(0.1):
  File "/Users/reuslujun/opt/anaconda3/envs/sanic/lib/python3.8/multiprocessing/connection.py", line 257, in poll
    return self._poll(timeout)
  File "/Users/reuslujun/opt/anaconda3/envs/sanic/lib/python3.8/multiprocessing/connection.py", line 424, in _poll
    r = wait([self], timeout)
  File "/Users/reuslujun/opt/anaconda3/envs/sanic/lib/python3.8/multiprocessing/connection.py", line 931, in wait
    ready = selector.select(timeout)
  File "/Users/reuslujun/opt/anaconda3/envs/sanic/lib/python3.8/selectors.py", line 415, in select
    fd_event_list = self._selector.poll(timeout)
  File "/Users/reuslujun/opt/anaconda3/envs/sanic/lib/python3.8/site-packages/sanic/worker/manager.py", line 293, in shutdown_signal
    self.shutdown()
  File "/Users/reuslujun/opt/anaconda3/envs/sanic/lib/python3.8/site-packages/sanic/worker/manager.py", line 298, in shutdown
    process.terminate()
  File "/Users/reuslujun/opt/anaconda3/envs/sanic/lib/python3.8/site-packages/sanic/worker/process.py", line 77, in terminate
    self.set_state(ProcessState.TERMINATED, force=True)
  File "/Users/reuslujun/opt/anaconda3/envs/sanic/lib/python3.8/site-packages/sanic/worker/process.py", line 41, in set_state
    **self.worker_state[self.name],
  File "<string>", line 2, in __getitem__
  File "/Users/reuslujun/opt/anaconda3/envs/sanic/lib/python3.8/multiprocessing/managers.py", line 835, in _callmethod
    kind, result = conn.recv()
  File "/Users/reuslujun/opt/anaconda3/envs/sanic/lib/python3.8/multiprocessing/connection.py", line 250, in recv
    buf = self._recv_bytes()
  File "/Users/reuslujun/opt/anaconda3/envs/sanic/lib/python3.8/multiprocessing/connection.py", line 414, in _recv_bytes
    buf = self._recv(4)
  File "/Users/reuslujun/opt/anaconda3/envs/sanic/lib/python3.8/multiprocessing/connection.py", line 383, in _recv
    raise EOFError
EOFError
2023-09-01 14:09:38,953 [ERROR] - Experienced exception while trying to serve
Traceback (most recent call last):
  File "/Users/reuslujun/opt/anaconda3/envs/sanic/lib/python3.8/site-packages/sanic/mixins/startup.py", line 880, in serve
    manager.run()
  File "/Users/reuslujun/opt/anaconda3/envs/sanic/lib/python3.8/site-packages/sanic/worker/manager.py", line 122, in run
    self.monitor()
  File "/Users/reuslujun/opt/anaconda3/envs/sanic/lib/python3.8/site-packages/sanic/worker/manager.py", line 186, in monitor
    if self.monitor_subscriber.poll(0.1):
  File "/Users/reuslujun/opt/anaconda3/envs/sanic/lib/python3.8/multiprocessing/connection.py", line 257, in poll
    return self._poll(timeout)
  File "/Users/reuslujun/opt/anaconda3/envs/sanic/lib/python3.8/multiprocessing/connection.py", line 424, in _poll
    r = wait([self], timeout)
  File "/Users/reuslujun/opt/anaconda3/envs/sanic/lib/python3.8/multiprocessing/connection.py", line 931, in wait
    ready = selector.select(timeout)
  File "/Users/reuslujun/opt/anaconda3/envs/sanic/lib/python3.8/selectors.py", line 415, in select
    fd_event_list = self._selector.poll(timeout)
  File "/Users/reuslujun/opt/anaconda3/envs/sanic/lib/python3.8/site-packages/sanic/worker/manager.py", line 293, in shutdown_signal
    self.shutdown()
  File "/Users/reuslujun/opt/anaconda3/envs/sanic/lib/python3.8/site-packages/sanic/worker/manager.py", line 298, in shutdown
    process.terminate()
  File "/Users/reuslujun/opt/anaconda3/envs/sanic/lib/python3.8/site-packages/sanic/worker/process.py", line 77, in terminate
    self.set_state(ProcessState.TERMINATED, force=True)
  File "/Users/reuslujun/opt/anaconda3/envs/sanic/lib/python3.8/site-packages/sanic/worker/process.py", line 41, in set_state
    **self.worker_state[self.name],
  File "<string>", line 2, in __getitem__
  File "/Users/reuslujun/opt/anaconda3/envs/sanic/lib/python3.8/multiprocessing/managers.py", line 835, in _callmethod
    kind, result = conn.recv()
  File "/Users/reuslujun/opt/anaconda3/envs/sanic/lib/python3.8/multiprocessing/connection.py", line 250, in recv
    buf = self._recv_bytes()
  File "/Users/reuslujun/opt/anaconda3/envs/sanic/lib/python3.8/multiprocessing/connection.py", line 414, in _recv_bytes
    buf = self._recv(4)
  File "/Users/reuslujun/opt/anaconda3/envs/sanic/lib/python3.8/multiprocessing/connection.py", line 383, in _recv
    raise EOFError
EOFError
[2023-09-01 14:09:38 +0800] [88898] [INFO] Server Stopped
2023-09-01 14:09:38,954 [INFO] - Server Stopped
Traceback (most recent call last):
  File "/Users/reuslujun/PycharmProjects/SanicStudy/test.py", line 24, in <module>
    app.run('localhost', 9999)
  File "/Users/reuslujun/opt/anaconda3/envs/sanic/lib/python3.8/site-packages/sanic/mixins/startup.py", line 215, in run
    serve(primary=self)  # type: ignore
  File "/Users/reuslujun/opt/anaconda3/envs/sanic/lib/python3.8/site-packages/sanic/mixins/startup.py", line 880, in serve
    manager.run()
  File "/Users/reuslujun/opt/anaconda3/envs/sanic/lib/python3.8/site-packages/sanic/worker/manager.py", line 122, in run
    self.monitor()
  File "/Users/reuslujun/opt/anaconda3/envs/sanic/lib/python3.8/site-packages/sanic/worker/manager.py", line 186, in monitor
    if self.monitor_subscriber.poll(0.1):
  File "/Users/reuslujun/opt/anaconda3/envs/sanic/lib/python3.8/multiprocessing/connection.py", line 257, in poll
    return self._poll(timeout)
  File "/Users/reuslujun/opt/anaconda3/envs/sanic/lib/python3.8/multiprocessing/connection.py", line 424, in _poll
    r = wait([self], timeout)
  File "/Users/reuslujun/opt/anaconda3/envs/sanic/lib/python3.8/multiprocessing/connection.py", line 931, in wait
    ready = selector.select(timeout)
  File "/Users/reuslujun/opt/anaconda3/envs/sanic/lib/python3.8/selectors.py", line 415, in select
    fd_event_list = self._selector.poll(timeout)
  File "/Users/reuslujun/opt/anaconda3/envs/sanic/lib/python3.8/site-packages/sanic/worker/manager.py", line 293, in shutdown_signal
    self.shutdown()
  File "/Users/reuslujun/opt/anaconda3/envs/sanic/lib/python3.8/site-packages/sanic/worker/manager.py", line 298, in shutdown
    process.terminate()
  File "/Users/reuslujun/opt/anaconda3/envs/sanic/lib/python3.8/site-packages/sanic/worker/process.py", line 77, in terminate
    self.set_state(ProcessState.TERMINATED, force=True)
  File "/Users/reuslujun/opt/anaconda3/envs/sanic/lib/python3.8/site-packages/sanic/worker/process.py", line 41, in set_state
    **self.worker_state[self.name],
  File "<string>", line 2, in __getitem__
  File "/Users/reuslujun/opt/anaconda3/envs/sanic/lib/python3.8/multiprocessing/managers.py", line 835, in _callmethod
    kind, result = conn.recv()
  File "/Users/reuslujun/opt/anaconda3/envs/sanic/lib/python3.8/multiprocessing/connection.py", line 250, in recv
    buf = self._recv_bytes()
  File "/Users/reuslujun/opt/anaconda3/envs/sanic/lib/python3.8/multiprocessing/connection.py", line 414, in _recv_bytes
    buf = self._recv(4)
  File "/Users/reuslujun/opt/anaconda3/envs/sanic/lib/python3.8/multiprocessing/connection.py", line 383, in _recv
    raise EOFError
EOFError
